Workbook

Sheet Resumen
A1: Comparativa inversión de medios MX 2026 — Plataformas vs tabla actual vs tabla nueva
A2: Tabla actual: papyrus-data-mx.habi_wh_bi.resumen_inversiones_mkt_mx · Tabla nueva: papyrus-master.sellers_comercial_global_dwh.sellers_inversion_marketing_regiones_global_dwh (pais = Mexico, columna spend en USD) · Plataformas: cuentas "Sellers USD". Ene – 22 sep 2026.
A4: Plataforma | B4: Gasto plataforma (USD) | C4: Tabla actual | D4: Tabla nueva | E4: ① Actual vs Plat. | F4: ② Nueva vs Plat. | G4: ③ Nueva vs Actual | H4: Veredicto tabla nueva
A5: Meta | B5: =Gasto!C14 | C5: =Gasto!D14 | D5: =Gasto!E14 | E5: =IFERROR(C5/B5-1,"") | F5: =IFERROR(D5/B5-1,"") | G5: =IFERROR(D5/C5-1,"") | H5: Falla: divide el gasto en USD entre ~17 como si fuera MXN
A6: Google | B6: =Gasto!C25 | C6: =Gasto!D25 | D6: =Gasto!E25 | E6: =IFERROR(C6/B6-1,"") | F6: =IFERROR(D6/B6-1,"") | G6: =IFERROR(D6/C6-1,"") | H6: Falla: duplica el renglón original y copia clics/impresiones
A7: TikTok | B7: =Gasto!C36 | C7: =Gasto!D36 | D7: =Gasto!E36 | E7: =IFERROR(C7/B7-1,"") | F7: =IFERROR(D7/B7-1,"") | G7: =IFERROR(D7/C7-1,"") | H7: Falla: suma cargos extra de US$6.96 (área "otros")
A8: Bing | B8: =Gasto!C47 | C8: =Gasto!D47 | D8: =Gasto!E47 | E8: =IFERROR(C8/B8-1,"") | F8: =IFERROR(D8/B8-1,"") | G8: =IFERROR(D8/C8-1,"") | H8: Falla: duplica el renglón original y copia clics/impresiones
A9: TOTAL | B9: =SUM(B5:B8) | C9: =SUM(C5:C8) | D9: =SUM(D5:D8) | E9: =IFERROR(C9/B9-1,"") | F9: =IFERROR(D9/B9-1,"") | G9: =IFERROR(D9/C9-1,"") | H9: La tabla actual cuadra; la nueva no es usable sin corrección
A11: Conclusiones
A12: 1. La tabla actual (resumen_inversiones_mkt_mx) cuadra con las plataformas: en Meta, Google y TikTok la diferencia es de menos de US$20 por mes (≤0.3%). Bing queda entre 1.7% y 3.4% abajo en abr–jul (faltan US$17–48 por mes), a revisar aparte; ene–mar, ago y sep cuadran.
A13: 2. La tabla nueva NO cuadra en ninguna plataforma tal como viene. Sumando su columna spend, mes a mes: Meta −94% a −95%, Google +49% a +72%, Bing +44% a +77%, TikTok −2% a +25%.
A14: 3. Con la corrección de duplicados, Google y Bing de la tabla nueva quedan iguales a la tabla actual. Meta y TikTok requieren arreglo en origen (Data Engineering).
A15: 4. Detalle de cada falla, con ejemplos y consultas para reproducirla: hoja "Hallazgos para DE".

Sheet Gasto
A1: Gasto — México 2026 (USD)
A2: Gasto en USD. Plataforma = total del reporte en el administrador de anuncios. Tabla nueva = SUM(spend) directo, sin corregir.
C3: Valores | G3: Diferencia % (vs. referencia) | K3: Diferencia absoluta
A4: Plataforma | B4: Mes | C4: Plataforma (fuente) | D4: Tabla actual | E4: Tabla nueva | F4: Tabla nueva corregida* | G4: ① Actual vs Plataforma | H4: ② Nueva vs Plataforma | I4: ③ Nueva vs Actual | J4: Nueva corregida vs Plataforma | K4: ① Dif. USD / unid. | L4: ② Dif. USD / unid.
A5: Meta | B5: Ene | C5: 148246.65 | D5: 148263 | E5: 7310.73 | F5: 7310.73 | G5: =IFERROR(D5/C5-1,"") | H5: =IFERROR(E5/C5-1,"") | I5: =IFERROR(E5/D5-1,"") | J5: =IFERROR(F5/C5-1,"") | K5: =D5-C5 | L5: =E5-C5
A6: Meta | B6: Feb | C6: 136913.77 | D6: 136916 | E6: 7947.05 | F6: 7947.05 | G6: =IFERROR(D6/C6-1,"") | H6: =IFERROR(E6/C6-1,"") | I6: =IFERROR(E6/D6-1,"") | J6: =IFERROR(F6/C6-1,"") | K6: =D6-C6 | L6: =E6-C6
A7: Meta | B7: Mar | C7: 166617.46 | D7: 166622 | E7: 9374.93 | F7: 9374.93 | G7: =IFERROR(D7/C7-1,"") | H7: =IFERROR(E7/C7-1,"") | I7: =IFERROR(E7/D7-1,"") | J7: =IFERROR(F7/C7-1,"") | K7: =D7-C7 | L7: =E7-C7
A8: Meta | B8: Abr | C8: 167096.54 | D8: 167107 | E8: 9582.73 | F8: 9582.73 | G8: =IFERROR(D8/C8-1,"") | H8: =IFERROR(E8/C8-1,"") | I8: =IFERROR(E8/D8-1,"") | J8: =IFERROR(F8/C8-1,"") | K8: =D8-C8 | L8: =E8-C8
A9: Meta | B9: May | C9: 167442.35 | D9: 167447 | E9: 9670.24 | F9: 9670.24 | G9: =IFERROR(D9/C9-1,"") | H9: =IFERROR(E9/C9-1,"") | I9: =IFERROR(E9/D9-1,"") | J9: =IFERROR(F9/C9-1,"") | K9: =D9-C9 | L9: =E9-C9
A10: Meta | B10: Jun | C10: 167014.12 | D10: 167012 | E10: 9607.87 | F10: 9607.87 | G10: =IFERROR(D10/C10-1,"") | H10: =IFERROR(E10/C10-1,"") | I10: =IFERROR(E10/D10-1,"") | J10: =IFERROR(F10/C10-1,"") | K10: =D10-C10 | L10: =E10-C10
A11: Meta | B11: Jul | C11: 172124.72 | D11: 172119 | E11: 9854.69 | F11: 9854.69 | G11: =IFERROR(D11/C11-1,"") | H11: =IFERROR(E11/C11-1,"") | I11: =IFERROR(E11/D11-1,"") | J11: =IFERROR(F11/C11-1,"") | K11: =D11-C11 | L11: =E11-C11
A12: Meta | B12: Ago | C12: 185994.11 | D12: 186002 | E12: 10900.41 | F12: 10900.41 | G12: =IFERROR(D12/C12-1,"") | H12: =IFERROR(E12/C12-1,"") | I12: =IFERROR(E12/D12-1,"") | J12: =IFERROR(F12/C12-1,"") | K12: =D12-C12 | L12: =E12-C12
A13: Meta | B13: Sep* | C13: 137430.7 | D13: 137430 | E13: 8062.98 | F13: 8062.98 | G13: =IFERROR(D13/C13-1,"") | H13: =IFERROR(E13/C13-1,"") | I13: =IFERROR(E13/D13-1,"") | J13: =IFERROR(F13/C13-1,"") | K13: =D13-C13 | L13: =E13-C13
A14: Meta | B14: Total 2026 | C14: =SUM(C5:C13) | D14: =SUM(D5:D13) | E14: =SUM(E5:E13) | F14: =SUM(F5:F13) | G14: =IFERROR(D14/C14-1,"") | H14: =IFERROR(E14/C14-1,"") | I14: =IFERROR(E14/D14-1,"") | J14: =IFERROR(F14/C14-1,"") | K14: =D14-C14 | L14: =E14-C14
A16: Google | B16: Ene | C16: 47406.58 | D16: 47417 | E16: 81588 | F16: 47417 | G16: =IFERROR(D16/C16-1,"") | H16: =IFERROR(E16/C16-1,"") | I16: =IFERROR(E16/D16-1,"") | J16: =IFERROR(F16/C16-1,"") | K16: =D16-C16 | L16: =E16-C16
A17: Google | B17: Feb | C17: 49379.15 | D17: 49370 | E17: 80722 | F17: 49370 | G17: =IFERROR(D17/C17-1,"") | H17: =IFERROR(E17/C17-1,"") | I17: =IFERROR(E17/D17-1,"") | J17: =IFERROR(F17/C17-1,"") | K17: =D17-C17 | L17: =E17-C17
A18: Google | B18: Mar | C18: 56981.06 | D18: 56985 | E18: 95669 | F18: 56985 | G18: =IFERROR(D18/C18-1,"") | H18: =IFERROR(E18/C18-1,"") | I18: =IFERROR(E18/D18-1,"") | J18: =IFERROR(F18/C18-1,"") | K18: =D18-C18 | L18: =E18-C18
A19: Google | B19: Abr | C19: 50894.19 | D19: 50889 | E19: 83963 | F19: 50889 | G19: =IFERROR(D19/C19-1,"") | H19: =IFERROR(E19/C19-1,"") | I19: =IFERROR(E19/D19-1,"") | J19: =IFERROR(F19/C19-1,"") | K19: =D19-C19 | L19: =E19-C19
A20: Google | B20: May | C20: 50617.67 | D20: 50623 | E20: 82513 | F20: 50623 | G20: =IFERROR(D20/C20-1,"") | H20: =IFERROR(E20/C20-1,"") | I20: =IFERROR(E20/D20-1,"") | J20: =IFERROR(F20/C20-1,"") | K20: =D20-C20 | L20: =E20-C20
A21: Google | B21: Jun | C21: 54855.48 | D21: 54845 | E21: 81651 | F21: 54845 | G21: =IFERROR(D21/C21-1,"") | H21: =IFERROR(E21/C21-1,"") | I21: =IFERROR(E21/D21-1,"") | J21: =IFERROR(F21/C21-1,"") | K21: =D21-C21 | L21: =E21-C21
A22: Google | B22: Jul | C22: 63313.33 | D22: 63316 | E22: 96511 | F22: 63316 | G22: =IFERROR(D22/C22-1,"") | H22: =IFERROR(E22/C22-1,"") | I22: =IFERROR(E22/D22-1,"") | J22: =IFERROR(F22/C22-1,"") | K22: =D22-C22 | L22: =E22-C22
A23: Google | B23: Ago | C23: 55253.17 | D23: 55244 | E23: 82168 | F23: 55244 | G23: =IFERROR(D23/C23-1,"") | H23: =IFERROR(E23/C23-1,"") | I23: =IFERROR(E23/D23-1,"") | J23: =IFERROR(F23/C23-1,"") | K23: =D23-C23 | L23: =E23-C23
A24: Google | B24: Sep* | C24: 30136.15 | D24: 30139 | E24: 48824 | F24: 30140 | G24: =IFERROR(D24/C24-1,"") | H24: =IFERROR(E24/C24-1,"") | I24: =IFERROR(E24/D24-1,"") | J24: =IFERROR(F24/C24-1,"") | K24: =D24-C24 | L24: =E24-C24
A25: Google | B25: Total 2026 | C25: =SUM(C16:C24) | D25: =SUM(D16:D24) | E25: =SUM(E16:E24) | F25: =SUM(F16:F24) | G25: =IFERROR(D25/C25-1,"") | H25: =IFERROR(E25/C25-1,"") | I25: =IFERROR(E25/D25-1,"") | J25: =IFERROR(F25/C25-1,"") | K25: =D25-C25 | L25: =E25-C25
A27: TikTok | B27: Ene | C27: 3873.17 | D27: 3860 | E27: 4848.32 | F27: 4848.32 | G27: =IFERROR(D27/C27-1,"") | H27: =IFERROR(E27/C27-1,"") | I27: =IFERROR(E27/D27-1,"") | J27: =IFERROR(F27/C27-1,"") | K27: =D27-C27 | L27: =E27-C27
A28: TikTok | B28: Feb | C28: 3687.33 | D28: 3687 | E28: 4222.92 | F28: 4222.92 | G28: =IFERROR(D28/C28-1,"") | H28: =IFERROR(E28/C28-1,"") | I28: =IFERROR(E28/D28-1,"") | J28: =IFERROR(F28/C28-1,"") | K28: =D28-C28 | L28: =E28-C28
A29: TikTok | B29: Mar | C29: 4238.89 | D29: 4238 | E29: 4801.76 | F29: 4801.76 | G29: =IFERROR(D29/C29-1,"") | H29: =IFERROR(E29/C29-1,"") | I29: =IFERROR(E29/D29-1,"") | J29: =IFERROR(F29/C29-1,"") | K29: =D29-C29 | L29: =E29-C29
A30: TikTok | B30: Abr | C30: 3904.44 | D30: 3905 | E30: 4197.32 | F30: 4197.32 | G30: =IFERROR(D30/C30-1,"") | H30: =IFERROR(E30/C30-1,"") | I30: =IFERROR(E30/D30-1,"") | J30: =IFERROR(F30/C30-1,"") | K30: =D30-C30 | L30: =E30-C30
A31: TikTok | B31: May | C31: 2649.29 | D31: 2650 | E31: 3067.6 | F31: 3067.6 | G31: =IFERROR(D31/C31-1,"") | H31: =IFERROR(E31/C31-1,"") | I31: =IFERROR(E31/D31-1,"") | J31: =IFERROR(F31/C31-1,"") | K31: =D31-C31 | L31: =E31-C31
A32: TikTok | B32: Jun | C32: 2235.73 | D32: 2238 | E32: 2523.36 | F32: 2523.36 | G32: =IFERROR(D32/C32-1,"") | H32: =IFERROR(E32/C32-1,"") | I32: =IFERROR(E32/D32-1,"") | J32: =IFERROR(F32/C32-1,"") | K32: =D32-C32 | L32: =E32-C32
A33: TikTok | B33: Jul | C33: 2141.26 | D33: 2140 | E33: 2494.96 | F33: 2494.96 | G33: =IFERROR(D33/C33-1,"") | H33: =IFERROR(E33/C33-1,"") | I33: =IFERROR(E33/D33-1,"") | J33: =IFERROR(F33/C33-1,"") | K33: =D33-C33 | L33: =E33-C33
A34: TikTok | B34: Ago | C34: 4745.34 | D34: 4745 | E34: 5099.96 | F34: 5099.96 | G34: =IFERROR(D34/C34-1,"") | H34: =IFERROR(E34/C34-1,"") | I34: =IFERROR(E34/D34-1,"") | J34: =IFERROR(F34/C34-1,"") | K34: =D34-C34 | L34: =E34-C34
A35: TikTok | B35: Sep* | C35: 4742.74 | D35: 4744 | E35: 4665.16 | F35: 4665.16 | G35: =IFERROR(D35/C35-1,"") | H35: =IFERROR(E35/C35-1,"") | I35: =IFERROR(E35/D35-1,"") | J35: =IFERROR(F35/C35-1,"") | K35: =D35-C35 | L35: =E35-C35
A36: TikTok | B36: Total 2026 | C36: =SUM(C27:C35) | D36: =SUM(D27:D35) | E36: =SUM(E27:E35) | F36: =SUM(F27:F35) | G36: =IFERROR(D36/C36-1,"") | H36: =IFERROR(E36/C36-1,"") | I36: =IFERROR(E36/D36-1,"") | J36: =IFERROR(F36/C36-1,"") | K36: =D36-C36 | L36: =E36-C36
A38: Bing | B38: Ene | C38: 1212.96 | D38: 1211.88 | E38: 1792.34 | F38: 1211.88 | G38: =IFERROR(D38/C38-1,"") | H38: =IFERROR(E38/C38-1,"") | I38: =IFERROR(E38/D38-1,"") | J38: =IFERROR(F38/C38-1,"") | K38: =D38-C38 | L38: =E38-C38
A39: Bing | B39: Feb | C39: 1190.8 | D39: 1185.37 | E39: 1774 | F39: 1185.37 | G39: =IFERROR(D39/C39-1,"") | H39: =IFERROR(E39/C39-1,"") | I39: =IFERROR(E39/D39-1,"") | J39: =IFERROR(F39/C39-1,"") | K39: =D39-C39 | L39: =E39-C39
A40: Bing | B40: Mar | C40: 1841.09 | D40: 1841.09 | E40: 2903.34 | F40: 1841.09 | G40: =IFERROR(D40/C40-1,"") | H40: =IFERROR(E40/C40-1,"") | I40: =IFERROR(E40/D40-1,"") | J40: =IFERROR(F40/C40-1,"") | K40: =D40-C40 | L40: =E40-C40
A41: Bing | B41: Abr | C41: 1804.13 | D41: 1763.43 | E41: 2813.24 | F41: 1763.43 | G41: =IFERROR(D41/C41-1,"") | H41: =IFERROR(E41/C41-1,"") | I41: =IFERROR(E41/D41-1,"") | J41: =IFERROR(F41/C41-1,"") | K41: =D41-C41 | L41: =E41-C41
A42: Bing | B42: May | C42: 1393.57 | D42: 1346.03 | E42: 2366.82 | F42: 1346.03 | G42: =IFERROR(D42/C42-1,"") | H42: =IFERROR(E42/C42-1,"") | I42: =IFERROR(E42/D42-1,"") | J42: =IFERROR(F42/C42-1,"") | K42: =D42-C42 | L42: =E42-C42
A43: Bing | B43: Jun | C43: 1777.63 | D43: 1729.83 | E43: 3013.41 | F43: 1729.83 | G43: =IFERROR(D43/C43-1,"") | H43: =IFERROR(E43/C43-1,"") | I43: =IFERROR(E43/D43-1,"") | J43: =IFERROR(F43/C43-1,"") | K43: =D43-C43 | L43: =E43-C43
...

Sheet Clics
A1: Clics — México 2026
A2: Clics. Meta = clics (todos); Google/Bing = clics; TikTok = Clicks (destination).
C3: Valores | G3: Diferencia % (vs. referencia) | K3: Diferencia absoluta
A4: Plataforma | B4: Mes | C4: Plataforma (fuente) | D4: Tabla actual | E4: Tabla nueva | F4: Tabla nueva corregida* | G4: ① Actual vs Plataforma | H4: ② Nueva vs Plataforma | I4: ③ Nueva vs Actual | J4: Nueva corregida vs Plataforma | K4: ① Dif. USD / unid. | L4: ② Dif. USD / unid.
A5: Meta | B5: Ene | C5: 614732 | D5: 614732 | E5: 614732 | F5: 614732 | G5: =IFERROR(D5/C5-1,"") | H5: =IFERROR(E5/C5-1,"") | I5: =IFERROR(E5/D5-1,"") | J5: =IFERROR(F5/C5-1,"") | K5: =D5-C5 | L5: =E5-C5
A6: Meta | B6: Feb | C6: 638745 | D6: 638745 | E6: 638745 | F6: 638745 | G6: =IFERROR(D6/C6-1,"") | H6: =IFERROR(E6/C6-1,"") | I6: =IFERROR(E6/D6-1,"") | J6: =IFERROR(F6/C6-1,"") | K6: =D6-C6 | L6: =E6-C6
A7: Meta | B7: Mar | C7: 636851 | D7: 636851 | E7: 636851 | F7: 636851 | G7: =IFERROR(D7/C7-1,"") | H7: =IFERROR(E7/C7-1,"") | I7: =IFERROR(E7/D7-1,"") | J7: =IFERROR(F7/C7-1,"") | K7: =D7-C7 | L7: =E7-C7
A8: Meta | B8: Abr | C8: 734579 | D8: 734579 | E8: 734579 | F8: 734579 | G8: =IFERROR(D8/C8-1,"") | H8: =IFERROR(E8/C8-1,"") | I8: =IFERROR(E8/D8-1,"") | J8: =IFERROR(F8/C8-1,"") | K8: =D8-C8 | L8: =E8-C8
A9: Meta | B9: May | C9: 900899 | D9: 900899 | E9: 900899 | F9: 900899 | G9: =IFERROR(D9/C9-1,"") | H9: =IFERROR(E9/C9-1,"") | I9: =IFERROR(E9/D9-1,"") | J9: =IFERROR(F9/C9-1,"") | K9: =D9-C9 | L9: =E9-C9
A10: Meta | B10: Jun | C10: 574795 | D10: 574795 | E10: 574795 | F10: 574795 | G10: =IFERROR(D10/C10-1,"") | H10: =IFERROR(E10/C10-1,"") | I10: =IFERROR(E10/D10-1,"") | J10: =IFERROR(F10/C10-1,"") | K10: =D10-C10 | L10: =E10-C10
A11: Meta | B11: Jul | C11: 519363 | D11: 519363 | E11: 519363 | F11: 519363 | G11: =IFERROR(D11/C11-1,"") | H11: =IFERROR(E11/C11-1,"") | I11: =IFERROR(E11/D11-1,"") | J11: =IFERROR(F11/C11-1,"") | K11: =D11-C11 | L11: =E11-C11
A12: Meta | B12: Ago | C12: 453569 | D12: 453569 | E12: 453569 | F12: 453569 | G12: =IFERROR(D12/C12-1,"") | H12: =IFERROR(E12/C12-1,"") | I12: =IFERROR(E12/D12-1,"") | J12: =IFERROR(F12/C12-1,"") | K12: =D12-C12 | L12: =E12-C12
A13: Meta | B13: Sep* | C13: 362887 | D13: 362883 | E13: 362865 | F13: 362865 | G13: =IFERROR(D13/C13-1,"") | H13: =IFERROR(E13/C13-1,"") | I13: =IFERROR(E13/D13-1,"") | J13: =IFERROR(F13/C13-1,"") | K13: =D13-C13 | L13: =E13-C13
A14: Meta | B14: Total 2026 | C14: =SUM(C5:C13) | D14: =SUM(D5:D13) | E14: =SUM(E5:E13) | F14: =SUM(F5:F13) | G14: =IFERROR(D14/C14-1,"") | H14: =IFERROR(E14/C14-1,"") | I14: =IFERROR(E14/D14-1,"") | J14: =IFERROR(F14/C14-1,"") | K14: =D14-C14 | L14: =E14-C14
A16: Google | B16: Ene | C16: 117094 | D16: 117094 | E16: 619782 | F16: 117094 | G16: =IFERROR(D16/C16-1,"") | H16: =IFERROR(E16/C16-1,"") | I16: =IFERROR(E16/D16-1,"") | J16: =IFERROR(F16/C16-1,"") | K16: =D16-C16 | L16: =E16-C16
A17: Google | B17: Feb | C17: 77017 | D17: 77017 | E17: 395281 | F17: 77017 | G17: =IFERROR(D17/C17-1,"") | H17: =IFERROR(E17/C17-1,"") | I17: =IFERROR(E17/D17-1,"") | J17: =IFERROR(F17/C17-1,"") | K17: =D17-C17 | L17: =E17-C17
A18: Google | B18: Mar | C18: 80411 | D18: 80411 | E18: 337083 | F18: 80411 | G18: =IFERROR(D18/C18-1,"") | H18: =IFERROR(E18/C18-1,"") | I18: =IFERROR(E18/D18-1,"") | J18: =IFERROR(F18/C18-1,"") | K18: =D18-C18 | L18: =E18-C18
A19: Google | B19: Abr | C19: 82102 | D19: 82102 | E19: 354518 | F19: 82102 | G19: =IFERROR(D19/C19-1,"") | H19: =IFERROR(E19/C19-1,"") | I19: =IFERROR(E19/D19-1,"") | J19: =IFERROR(F19/C19-1,"") | K19: =D19-C19 | L19: =E19-C19
A20: Google | B20: May | C20: 65439 | D20: 65439 | E20: 323623 | F20: 65439 | G20: =IFERROR(D20/C20-1,"") | H20: =IFERROR(E20/C20-1,"") | I20: =IFERROR(E20/D20-1,"") | J20: =IFERROR(F20/C20-1,"") | K20: =D20-C20 | L20: =E20-C20
A21: Google | B21: Jun | C21: 58716 | D21: 58716 | E21: 353292 | F21: 58716 | G21: =IFERROR(D21/C21-1,"") | H21: =IFERROR(E21/C21-1,"") | I21: =IFERROR(E21/D21-1,"") | J21: =IFERROR(F21/C21-1,"") | K21: =D21-C21 | L21: =E21-C21
A22: Google | B22: Jul | C22: 75049 | D22: 75049 | E22: 380041 | F22: 75049 | G22: =IFERROR(D22/C22-1,"") | H22: =IFERROR(E22/C22-1,"") | I22: =IFERROR(E22/D22-1,"") | J22: =IFERROR(F22/C22-1,"") | K22: =D22-C22 | L22: =E22-C22
A23: Google | B23: Ago | C23: 71007 | D23: 71007 | E23: 372527 | F23: 71007 | G23: =IFERROR(D23/C23-1,"") | H23: =IFERROR(E23/C23-1,"") | I23: =IFERROR(E23/D23-1,"") | J23: =IFERROR(F23/C23-1,"") | K23: =D23-C23 | L23: =E23-C23
A24: Google | B24: Sep* | C24: 38753 | D24: 38755 | E24: 110667 | F24: 38755 | G24: =IFERROR(D24/C24-1,"") | H24: =IFERROR(E24/C24-1,"") | I24: =IFERROR(E24/D24-1,"") | J24: =IFERROR(F24/C24-1,"") | K24: =D24-C24 | L24: =E24-C24
A25: Google | B25: Total 2026 | C25: =SUM(C16:C24) | D25: =SUM(D16:D24) | E25: =SUM(E16:E24) | F25: =SUM(F16:F24) | G25: =IFERROR(D25/C25-1,"") | H25: =IFERROR(E25/C25-1,"") | I25: =IFERROR(E25/D25-1,"") | J25: =IFERROR(F25/C25-1,"") | K25: =D25-C25 | L25: =E25-C25
A27: TikTok | B27: Ene | C27: 7318 | D27: 7281 | E27: 50967 | F27: 7281 | G27: =IFERROR(D27/C27-1,"") | H27: =IFERROR(E27/C27-1,"") | I27: =IFERROR(E27/D27-1,"") | J27: =IFERROR(F27/C27-1,"") | K27: =D27-C27 | L27: =E27-C27
A28: TikTok | B28: Feb | C28: 5031 | D28: 5031 | E28: 37526 | F28: 5031 | G28: =IFERROR(D28/C28-1,"") | H28: =IFERROR(E28/C28-1,"") | I28: =IFERROR(E28/D28-1,"") | J28: =IFERROR(F28/C28-1,"") | K28: =D28-C28 | L28: =E28-C28
A29: TikTok | B29: Mar | C29: 3910 | D29: 3910 | E29: 26157 | F29: 3910 | G29: =IFERROR(D29/C29-1,"") | H29: =IFERROR(E29/C29-1,"") | I29: =IFERROR(E29/D29-1,"") | J29: =IFERROR(F29/C29-1,"") | K29: =D29-C29 | L29: =E29-C29
A30: TikTok | B30: Abr | C30: 3378 | D30: 3378 | E30: 22595 | F30: 3378 | G30: =IFERROR(D30/C30-1,"") | H30: =IFERROR(E30/C30-1,"") | I30: =IFERROR(E30/D30-1,"") | J30: =IFERROR(F30/C30-1,"") | K30: =D30-C30 | L30: =E30-C30
A31: TikTok | B31: May | C31: 2919 | D31: 2919 | E31: 14273 | F31: 2919 | G31: =IFERROR(D31/C31-1,"") | H31: =IFERROR(E31/C31-1,"") | I31: =IFERROR(E31/D31-1,"") | J31: =IFERROR(F31/C31-1,"") | K31: =D31-C31 | L31: =E31-C31
A32: TikTok | B32: Jun | C32: 4704 | D32: 4704 | E32: 30006 | F32: 4704 | G32: =IFERROR(D32/C32-1,"") | H32: =IFERROR(E32/C32-1,"") | I32: =IFERROR(E32/D32-1,"") | J32: =IFERROR(F32/C32-1,"") | K32: =D32-C32 | L32: =E32-C32
A33: TikTok | B33: Jul | C33: 7620 | D33: 7620 | E33: 51128 | F33: 7620 | G33: =IFERROR(D33/C33-1,"") | H33: =IFERROR(E33/C33-1,"") | I33: =IFERROR(E33/D33-1,"") | J33: =IFERROR(F33/C33-1,"") | K33: =D33-C33 | L33: =E33-C33
A34: TikTok | B34: Ago | C34: 15990 | D34: 15990 | E34: 100722 | F34: 15990 | G34: =IFERROR(D34/C34-1,"") | H34: =IFERROR(E34/C34-1,"") | I34: =IFERROR(E34/D34-1,"") | J34: =IFERROR(F34/C34-1,"") | K34: =D34-C34 | L34: =E34-C34
A35: TikTok | B35: Sep* | C35: 14186 | D35: 14186 | E35: 73168 | F35: 14186 | G35: =IFERROR(D35/C35-1,"") | H35: =IFERROR(E35/C35-1,"") | I35: =IFERROR(E35/D35-1,"") | J35: =IFERROR(F35/C35-1,"") | K35: =D35-C35 | L35: =E35-C35
A36: TikTok | B36: Total 2026 | C36: =SUM(C27:C35) | D36: =SUM(D27:D35) | E36: =SUM(E27:E35) | F36: =SUM(F27:F35) | G36: =IFERROR(D36/C36-1,"") | H36: =IFERROR(E36/C36-1,"") | I36: =IFERROR(E36/D36-1,"") | J36: =IFERROR(F36/C36-1,"") | K36: =D36-C36 | L36: =E36-C36
A38: Bing | B38: Ene | C38: 7558 | D38: 7554 | E38: 21378 | F38: 7554 | G38: =IFERROR(D38/C38-1,"") | H38: =IFERROR(E38/C38-1,"") | I38: =IFERROR(E38/D38-1,"") | J38: =IFERROR(F38/C38-1,"") | K38: =D38-C38 | L38: =E38-C38
A39: Bing | B39: Feb | C39: 5577 | D39: 5544 | E39: 16396 | F39: 5544 | G39: =IFERROR(D39/C39-1,"") | H39: =IFERROR(E39/C39-1,"") | I39: =IFERROR(E39/D39-1,"") | J39: =IFERROR(F39/C39-1,"") | K39: =D39-C39 | L39: =E39-C39
A40: Bing | B40: Mar | C40: 6985 | D40: 6984 | E40: 21292 | F40: 6984 | G40: =IFERROR(D40/C40-1,"") | H40: =IFERROR(E40/C40-1,"") | I40: =IFERROR(E40/D40-1,"") | J40: =IFERROR(F40/C40-1,"") | K40: =D40-C40 | L40: =E40-C40
A41: Bing | B41: Abr | C41: 7545 | D41: 7308 | E41: 24603 | F41: 7308 | G41: =IFERROR(D41/C41-1,"") | H41: =IFERROR(E41/C41-1,"") | I41: =IFERROR(E41/D41-1,"") | J41: =IFERROR(F41/C41-1,"") | K41: =D41-C41 | L41: =E41-C41
A42: Bing | B42: May | C42: 4090 | D42: 3907 | E42: 10357 | F42: 3907 | G42: =IFERROR(D42/C42-1,"") | H42: =IFERROR(E42/C42-1,"") | I42: =IFERROR(E42/D42-1,"") | J42: =IFERROR(F42/C42-1,"") | K42: =D42-C42 | L42: =E42-C42
A43: Bing | B43: Jun | C43: 6263 | D43: 6076 | E43: 12720 | F43: 6076 | G43: =IFERROR(D43/C43-1,"") | H43: =IFERROR(E43/C43-1,"") | I43: =IFERROR(E43/D43-1,"") | J43: =IFERROR(F43/C43-1,"") | K43: =D43-C43 | L43: =E43-C43
...

Sheet Impresiones
A1: Impresiones — México 2026
A2: Impresiones.
C3: Valores | G3: Diferencia % (vs. referencia) | K3: Diferencia absoluta
A4: Plataforma | B4: Mes | C4: Plataforma (fuente) | D4: Tabla actual | E4: Tabla nueva | F4: Tabla nueva corregida* | G4: ① Actual vs Plataforma | H4: ② Nueva vs Plataforma | I4: ③ Nueva vs Actual | J4: Nueva corregida vs Plataforma | K4: ① Dif. USD / unid. | L4: ② Dif. USD / unid.
A5: Meta | B5: Ene | C5: 56395571 | D5: 56395571 | E5: 56395571 | F5: 56395571 | G5: =IFERROR(D5/C5-1,"") | H5: =IFERROR(E5/C5-1,"") | I5: =IFERROR(E5/D5-1,"") | J5: =IFERROR(F5/C5-1,"") | K5: =D5-C5 | L5: =E5-C5
A6: Meta | B6: Feb | C6: 49448508 | D6: 49448508 | E6: 49448508 | F6: 49448508 | G6: =IFERROR(D6/C6-1,"") | H6: =IFERROR(E6/C6-1,"") | I6: =IFERROR(E6/D6-1,"") | J6: =IFERROR(F6/C6-1,"") | K6: =D6-C6 | L6: =E6-C6
A7: Meta | B7: Mar | C7: 51977449 | D7: 51977449 | E7: 51977449 | F7: 51977449 | G7: =IFERROR(D7/C7-1,"") | H7: =IFERROR(E7/C7-1,"") | I7: =IFERROR(E7/D7-1,"") | J7: =IFERROR(F7/C7-1,"") | K7: =D7-C7 | L7: =E7-C7
A8: Meta | B8: Abr | C8: 54828315 | D8: 54828315 | E8: 54828315 | F8: 54828315 | G8: =IFERROR(D8/C8-1,"") | H8: =IFERROR(E8/C8-1,"") | I8: =IFERROR(E8/D8-1,"") | J8: =IFERROR(F8/C8-1,"") | K8: =D8-C8 | L8: =E8-C8
A9: Meta | B9: May | C9: 47202597 | D9: 47202597 | E9: 47202597 | F9: 47202597 | G9: =IFERROR(D9/C9-1,"") | H9: =IFERROR(E9/C9-1,"") | I9: =IFERROR(E9/D9-1,"") | J9: =IFERROR(F9/C9-1,"") | K9: =D9-C9 | L9: =E9-C9
A10: Meta | B10: Jun | C10: 44496540 | D10: 44496540 | E10: 44496540 | F10: 44496540 | G10: =IFERROR(D10/C10-1,"") | H10: =IFERROR(E10/C10-1,"") | I10: =IFERROR(E10/D10-1,"") | J10: =IFERROR(F10/C10-1,"") | K10: =D10-C10 | L10: =E10-C10
A11: Meta | B11: Jul | C11: 54292782 | D11: 54292782 | E11: 54292782 | F11: 54292782 | G11: =IFERROR(D11/C11-1,"") | H11: =IFERROR(E11/C11-1,"") | I11: =IFERROR(E11/D11-1,"") | J11: =IFERROR(F11/C11-1,"") | K11: =D11-C11 | L11: =E11-C11
A12: Meta | B12: Ago | C12: 51897260 | D12: 51897260 | E12: 51897260 | F12: 51897260 | G12: =IFERROR(D12/C12-1,"") | H12: =IFERROR(E12/C12-1,"") | I12: =IFERROR(E12/D12-1,"") | J12: =IFERROR(F12/C12-1,"") | K12: =D12-C12 | L12: =E12-C12
A13: Meta | B13: Sep* | C13: 36346812 | D13: 36346348 | E13: 36344559 | F13: 36344559 | G13: =IFERROR(D13/C13-1,"") | H13: =IFERROR(E13/C13-1,"") | I13: =IFERROR(E13/D13-1,"") | J13: =IFERROR(F13/C13-1,"") | K13: =D13-C13 | L13: =E13-C13
A14: Meta | B14: Total 2026 | C14: =SUM(C5:C13) | D14: =SUM(D5:D13) | E14: =SUM(E5:E13) | F14: =SUM(F5:F13) | G14: =IFERROR(D14/C14-1,"") | H14: =IFERROR(E14/C14-1,"") | I14: =IFERROR(E14/D14-1,"") | J14: =IFERROR(F14/C14-1,"") | K14: =D14-C14 | L14: =E14-C14
A16: Google | B16: Ene | C16: 11985029 | D16: 11985029 | E16: 87079693 | F16: 11985029 | G16: =IFERROR(D16/C16-1,"") | H16: =IFERROR(E16/C16-1,"") | I16: =IFERROR(E16/D16-1,"") | J16: =IFERROR(F16/C16-1,"") | K16: =D16-C16 | L16: =E16-C16
A17: Google | B17: Feb | C17: 7720563 | D17: 7720563 | E17: 50763579 | F17: 7720563 | G17: =IFERROR(D17/C17-1,"") | H17: =IFERROR(E17/C17-1,"") | I17: =IFERROR(E17/D17-1,"") | J17: =IFERROR(F17/C17-1,"") | K17: =D17-C17 | L17: =E17-C17
A18: Google | B18: Mar | C18: 6051327 | D18: 6051327 | E18: 33926647 | F18: 6051327 | G18: =IFERROR(D18/C18-1,"") | H18: =IFERROR(E18/C18-1,"") | I18: =IFERROR(E18/D18-1,"") | J18: =IFERROR(F18/C18-1,"") | K18: =D18-C18 | L18: =E18-C18
A19: Google | B19: Abr | C19: 5554588 | D19: 5554588 | E19: 36515516 | F19: 5554588 | G19: =IFERROR(D19/C19-1,"") | H19: =IFERROR(E19/C19-1,"") | I19: =IFERROR(E19/D19-1,"") | J19: =IFERROR(F19/C19-1,"") | K19: =D19-C19 | L19: =E19-C19
A20: Google | B20: May | C20: 3671540 | D20: 3671540 | E20: 24557956 | F20: 3671540 | G20: =IFERROR(D20/C20-1,"") | H20: =IFERROR(E20/C20-1,"") | I20: =IFERROR(E20/D20-1,"") | J20: =IFERROR(F20/C20-1,"") | K20: =D20-C20 | L20: =E20-C20
A21: Google | B21: Jun | C21: 2813676 | D21: 2813676 | E21: 18396204 | F21: 2813676 | G21: =IFERROR(D21/C21-1,"") | H21: =IFERROR(E21/C21-1,"") | I21: =IFERROR(E21/D21-1,"") | J21: =IFERROR(F21/C21-1,"") | K21: =D21-C21 | L21: =E21-C21
A22: Google | B22: Jul | C22: 2230047 | D22: 2230047 | E22: 11177087 | F22: 2230047 | G22: =IFERROR(D22/C22-1,"") | H22: =IFERROR(E22/C22-1,"") | I22: =IFERROR(E22/D22-1,"") | J22: =IFERROR(F22/C22-1,"") | K22: =D22-C22 | L22: =E22-C22
A23: Google | B23: Ago | C23: 1750643 | D23: 1750643 | E23: 8085571 | F23: 1750643 | G23: =IFERROR(D23/C23-1,"") | H23: =IFERROR(E23/C23-1,"") | I23: =IFERROR(E23/D23-1,"") | J23: =IFERROR(F23/C23-1,"") | K23: =D23-C23 | L23: =E23-C23
A24: Google | B24: Sep* | C24: 953214 | D24: 953210 | E24: 1990090 | F24: 953186 | G24: =IFERROR(D24/C24-1,"") | H24: =IFERROR(E24/C24-1,"") | I24: =IFERROR(E24/D24-1,"") | J24: =IFERROR(F24/C24-1,"") | K24: =D24-C24 | L24: =E24-C24
A25: Google | B25: Total 2026 | C25: =SUM(C16:C24) | D25: =SUM(D16:D24) | E25: =SUM(E16:E24) | F25: =SUM(F16:F24) | G25: =IFERROR(D25/C25-1,"") | H25: =IFERROR(E25/C25-1,"") | I25: =IFERROR(E25/D25-1,"") | J25: =IFERROR(F25/C25-1,"") | K25: =D25-C25 | L25: =E25-C25
A27: TikTok | B27: Ene | C27: 3309751 | D27: 3295790 | E27: 23069878 | F27: 3295790 | G27: =IFERROR(D27/C27-1,"") | H27: =IFERROR(E27/C27-1,"") | I27: =IFERROR(E27/D27-1,"") | J27: =IFERROR(F27/C27-1,"") | K27: =D27-C27 | L27: =E27-C27
A28: TikTok | B28: Feb | C28: 1969530 | D28: 1969530 | E28: 14655475 | F28: 1969530 | G28: =IFERROR(D28/C28-1,"") | H28: =IFERROR(E28/C28-1,"") | I28: =IFERROR(E28/D28-1,"") | J28: =IFERROR(F28/C28-1,"") | K28: =D28-C28 | L28: =E28-C28
A29: TikTok | B29: Mar | C29: 1585434 | D29: 1585437 | E29: 10645102 | F29: 1585437 | G29: =IFERROR(D29/C29-1,"") | H29: =IFERROR(E29/C29-1,"") | I29: =IFERROR(E29/D29-1,"") | J29: =IFERROR(F29/C29-1,"") | K29: =D29-C29 | L29: =E29-C29
A30: TikTok | B30: Abr | C30: 1288292 | D30: 1288292 | E30: 8631981 | F30: 1288292 | G30: =IFERROR(D30/C30-1,"") | H30: =IFERROR(E30/C30-1,"") | I30: =IFERROR(E30/D30-1,"") | J30: =IFERROR(F30/C30-1,"") | K30: =D30-C30 | L30: =E30-C30
A31: TikTok | B31: May | C31: 903281 | D31: 903281 | E31: 4416797 | F31: 903281 | G31: =IFERROR(D31/C31-1,"") | H31: =IFERROR(E31/C31-1,"") | I31: =IFERROR(E31/D31-1,"") | J31: =IFERROR(F31/C31-1,"") | K31: =D31-C31 | L31: =E31-C31
A32: TikTok | B32: Jun | C32: 426074 | D32: 426074 | E32: 2729170 | F32: 426074 | G32: =IFERROR(D32/C32-1,"") | H32: =IFERROR(E32/C32-1,"") | I32: =IFERROR(E32/D32-1,"") | J32: =IFERROR(F32/C32-1,"") | K32: =D32-C32 | L32: =E32-C32
A33: TikTok | B33: Jul | C33: 528460 | D33: 528460 | E33: 3544316 | F33: 528460 | G33: =IFERROR(D33/C33-1,"") | H33: =IFERROR(E33/C33-1,"") | I33: =IFERROR(E33/D33-1,"") | J33: =IFERROR(F33/C33-1,"") | K33: =D33-C33 | L33: =E33-C33
A34: TikTok | B34: Ago | C34: 3971263 | D34: 3971263 | E34: 24158505 | F34: 3971263 | G34: =IFERROR(D34/C34-1,"") | H34: =IFERROR(E34/C34-1,"") | I34: =IFERROR(E34/D34-1,"") | J34: =IFERROR(F34/C34-1,"") | K34: =D34-C34 | L34: =E34-C34
A35: TikTok | B35: Sep* | C35: 5199974 | D35: 5199974 | E35: 26109338 | F35: 5199974 | G35: =IFERROR(D35/C35-1,"") | H35: =IFERROR(E35/C35-1,"") | I35: =IFERROR(E35/D35-1,"") | J35: =IFERROR(F35/C35-1,"") | K35: =D35-C35 | L35: =E35-C35
A36: TikTok | B36: Total 2026 | C36: =SUM(C27:C35) | D36: =SUM(D27:D35) | E36: =SUM(E27:E35) | F36: =SUM(F27:F35) | G36: =IFERROR(D36/C36-1,"") | H36: =IFERROR(E36/C36-1,"") | I36: =IFERROR(E36/D36-1,"") | J36: =IFERROR(F36/C36-1,"") | K36: =D36-C36 | L36: =E36-C36
A38: Bing | B38: Ene | C38: 563902 | D38: 563507 | E38: 1674911 | F38: 563507 | G38: =IFERROR(D38/C38-1,"") | H38: =IFERROR(E38/C38-1,"") | I38: =IFERROR(E38/D38-1,"") | J38: =IFERROR(F38/C38-1,"") | K38: =D38-C38 | L38: =E38-C38
A39: Bing | B39: Feb | C39: 408978 | D39: 406634 | E39: 1237818 | F39: 406634 | G39: =IFERROR(D39/C39-1,"") | H39: =IFERROR(E39/C39-1,"") | I39: =IFERROR(E39/D39-1,"") | J39: =IFERROR(F39/C39-1,"") | K39: =D39-C39 | L39: =E39-C39
A40: Bing | B40: Mar | C40: 519198 | D40: 519196 | E40: 1756728 | F40: 519196 | G40: =IFERROR(D40/C40-1,"") | H40: =IFERROR(E40/C40-1,"") | I40: =IFERROR(E40/D40-1,"") | J40: =IFERROR(F40/C40-1,"") | K40: =D40-C40 | L40: =E40-C40
A41: Bing | B41: Abr | C41: 511256 | D41: 490977 | E41: 1820812 | F41: 490977 | G41: =IFERROR(D41/C41-1,"") | H41: =IFERROR(E41/C41-1,"") | I41: =IFERROR(E41/D41-1,"") | J41: =IFERROR(F41/C41-1,"") | K41: =D41-C41 | L41: =E41-C41
A42: Bing | B42: May | C42: 189629 | D42: 179048 | E42: 536888 | F42: 179048 | G42: =IFERROR(D42/C42-1,"") | H42: =IFERROR(E42/C42-1,"") | I42: =IFERROR(E42/D42-1,"") | J42: =IFERROR(F42/C42-1,"") | K42: =D42-C42 | L42: =E42-C42
A43: Bing | B43: Jun | C43: 316493 | D43: 307014 | E43: 729562 | F43: 307014 | G43: =IFERROR(D43/C43-1,"") | H43: =IFERROR(E43/C43-1,"") | I43: =IFERROR(E43/D43-1,"") | J43: =IFERROR(F43/C43-1,"") | K43: =D43-C43 | L43: =E43-C43
...

Sheet Hallazgos para DE
A1: Hallazgos en sellers_inversion_marketing_regiones_global_dwh (México) — qué revisar
A2: Cada caso tiene un ejemplo real y una consulta para reproducirlo. Valores en USD.
A4: # | B4: Problema | C4: Qué pasa (ejemplo real) | D4: Impacto | E4: Qué revisar / cómo debería quedar | F4: Consulta para reproducir
A5: 1 | B5: Renglón original duplicado después del prorrateo por área metropolitana | C5: Las campañas nacionales se reparten por área metropolitana (fuente = WEB / Lead Forms / Estudio Inmueble, 9 áreas). En algunas campañas-día, además de esos renglones repartidos, se queda el renglón ORIGINAL sin repartir (fuente NULL, area_metropolitana = "sin area metropolitana", area_metropolitana_id NULL). Ejemplo: 10-ago-2026, aw_tuhabi_mx_performance_max_nal_max_conv_price. Los 9 renglones repartidos suman US$557.90 y además existe el renglón original de US$558.00 → la tabla suma US$1,115.90; Google Ads reporta US$558. | D5: El gasto se cuenta dos veces. Ene–sep 2026: Google US$274,780 y Bing US$8,220 de gasto duplicado. | E5: Cuando una campaña-día se prorratea, el renglón original debe eliminarse (o no insertarse). Regla de control: para cada (date, plataforma, campana_original), SUM(spend) debe ser igual al gasto de la plataforma. Revisar por qué el borrado/reemplazo del original falla sólo en algunas campañas (en Google afecta a las de Max Val ROAS / conv_price; en Bing a las de brand y Max_Val_Roas). | F5: SELECT date, campana_original, area_metropolitana, fuente, spend, clicks, impressions FROM `papyrus-master.sellers_comercial_global_dwh.sellers_inversion_marketing_regiones_global_dwh` WHERE pais='Mexico' AND date='2026-08-10' AND campana_original='aw_tuhabi_mx_performance_max_nal_max_conv_price' ORDER BY area_metropolitana
A6: 2 | B6: Clics e impresiones copiados en cada área (no se prorratean) | C6: Al repartir por área, el gasto sí se reparte, pero clics e impresiones se copian completos en cada uno de los 9 renglones. Ejemplo: 10-ago-2026, aw_tuhabi_mx_performance_max_nal_max_conv_2_1. Los 9 renglones traen clicks = 414 e impressions = 14,375 cada uno → la tabla suma 3,726 clics; Google Ads reporta 414. En otras campañas (ej. conv_price) los renglones repartidos traen clicks/impressions en NULL y el valor sólo vive en el renglón original duplicado (hallazgo 1). | D6: Por campaña-día llega a x9. En el total mensual: Google clics x2.9–x6.0 e impresiones x2.1–x7.3; Bing x1.2–x3.7; TikTok x4.9–x7.5. Meta no tiene el problema. CPC, CTR y CPM calculados con esta tabla salen mal. | E6: Prorratear clics e impresiones con el mismo factor que el gasto (o dejarlos en un solo renglón). Regla de control: SUM(clicks) por campaña-día = clics de la plataforma. Unificar el tratamiento: hoy hay campañas con clics copiados y otras con NULL. | F6: SELECT date, campana_original, area_metropolitana, fuente, spend, clicks, impressions FROM `papyrus-master.sellers_comercial_global_dwh.sellers_inversion_marketing_regiones_global_dwh` WHERE pais='Mexico' AND date='2026-08-10' AND campana_original='aw_tuhabi_mx_performance_max_nal_max_conv_2_1'
A7: 3 | B7: Meta: gasto en USD tratado como MXN | C7: La cuenta publicitaria Habi Mexico Sellers (USD) (act 205661715114408) reporta en dólares. La tabla toma ese valor como pesos y lo divide entre el tipo de cambio (~17). Ejemplo: 27-jul-2026, FB_HabiWeb_LeadAds_ADVANTAGE_ConvLeadAds: valor_original = 175.89, moneda = "USD", conversion_mxn = 175.89, spend / conversion_usd = 10.09. Agosto 2026: Meta Ads Manager US$185,994.11 · tabla actual US$186,002 · tabla nueva US$10,900.41 (y conversion_mxn = 185,994.28, que en realidad son dólares). | D7: Meta queda 94% abajo en USD y 17 veces abajo en MXN. Es el ~75% de la inversión de MX: todo total, CPL y mix que use esta tabla sale mal. | E7: Si moneda = "USD", entonces spend = conversion_usd = valor_original y conversion_mxn = valor_original × tipo de cambio. Revisar la regla de moneda para Facebook MX: parece forzar MXN en lugar de leer la moneda de la cuenta. Las cuentas de Sellers MX y CO en Meta están en USD. Ojo: existe otra cuenta "Habi Mexico Sellers (MXN)" que NO debe usarse para Sellers. | F7: SELECT FORMAT_DATE('%Y-%m',date) mes, SUM(valor_original) valor_original, SUM(spend) spend_usd, SUM(conversion_mxn) mxn, STRING_AGG(DISTINCT moneda) moneda FROM `papyrus-master.sellers_comercial_global_dwh.sellers_inversion_marketing_regiones_global_dwh` WHERE pais='Mexico' AND plataforma='Facebook' AND date>='2026-01-01' GROUP BY 1 ORDER BY 1
A8: 4 | B8: TikTok Lead Forms: cargos extra de US$6.96 en área "otros" | C8: La campaña tuh-mex-sel-pai-per-lfr-tka-tlg-tad-nal-smrt trae más gasto que en TikTok, siempre en múltiplos de US$6.96. Parte cae en area_metropolitana = "otros" y aparece gasto incluso en días con US$0 en la plataforma (9, 15, 29 y 30 de ago). Ejemplo: 20-ago-2026. TikTok y la tabla actual: US$95.00. Tabla nueva: US$122.84 (US$101.96 repartido + US$20.88 en "otros" = 3 × 6.96). Agosto 2026: TikTok US$1,786.32 en esta campaña; tabla nueva US$2,142. | D8: TikTok queda entre 7% y 25% arriba cada mes (ene: +25%). En septiembre queda abajo (−2%). | E8: Explicar de dónde sale el costo de 6.96 y el área "otros". Parece un costo por lead (gasto ÷ leads) que se suma encima del gasto real en lugar de repartirlo. El total por campaña-día debe ser igual al gasto de TikTok. | F8: SELECT date, area_metropolitana, fuente, spend, clicks FROM `papyrus-master.sellers_comercial_global_dwh.sellers_inversion_marketing_regiones_global_dwh` WHERE pais='Mexico' AND date='2026-08-20' AND campana_original='tuh-mex-sel-pai-per-lfr-tka-tlg-tad-nal-smrt' ORDER BY area_metropolitana
A9: 5 | B9: Etiqueta de moneda inconsistente | C9: La columna moneda dice "USD" en todos los renglones de MX, pero valor_original a veces está en USD (Google, Bing, TikTok) y conversion_mxn = valor_original en Meta. | D9: Confunde a quien use valor_original o moneda para convertir. | E9: Que moneda refleje la moneda real de valor_original (la de la cuenta publicitaria) y que las 3 conversiones (usd, cop, mxn) partan de ella. | F9: (misma consulta del hallazgo 3)
A11: Prueba de aceptación sugerida: para cada plataforma y mes, SUM(spend), SUM(clicks) y SUM(impressions) de la tabla nueva deben ser iguales (±0.5%) a la hoja "Gasto"/"Clics"/"Impresiones" columna Plataforma; y SUM(conversion_mxn) = SUM(spend) × tipo de cambio del día.

Sheet Metodología
A1: Metodología y fuentes
A2: Cómo se construyó cada columna.
A4: Periodo | B4: 1-ene-2026 a 22-sep-2026 en todas las fuentes (plataformas y BigQuery). Septiembre es parcial.
A5: Meta | B5: Administrador de anuncios, cuenta "Habi Mexico Sellers (USD)" act 205661715114408, nivel campaña, todas las campañas. Importe gastado, impresiones, clics (todos). Leído el 23-sep-2026.
A6: Google | B6: Google Ads, cuenta "Habi Mexico Sellers (USD)" 905-246-3137, export por mes (googlespend.csv). Coste, impresiones, clics.
A7: TikTok | B7: TikTok Ads Manager, cuenta "Tuhabi MX Sellers USD" 7104688500875821058, nivel campaña. Spend, impressions, clicks (destination). Leído el 23-sep-2026.
A8: Bing | B8: Microsoft Advertising, cuenta "Habi Mexico Sellers (USD)" F145UHS4, export por mes (microsoft.csv). Spend, clicks, impressions.
A9: Cuentas excluidas | B9: No se usan las cuentas en MXN (p. ej. Meta "Habi Mexico Sellers (MXN)"), sólo las de Sellers en USD.
A10: Tabla actual | B10: papyrus-data-mx.habi_wh_bi.resumen_inversiones_mkt_mx: SUM(spend), SUM(clicks), SUM(impressions) por plataforma y mes. Está en USD.
A11: Tabla nueva | B11: papyrus-master.sellers_comercial_global_dwh.sellers_inversion_marketing_regiones_global_dwh con pais = 'Mexico': SUM(spend) (USD), SUM(clicks), SUM(impressions) directos.
A12: Tabla nueva corregida | B12: Por (date, plataforma, campana_original): si existe algún renglón con fuente NO nula (prorrateado), se descarta el renglón con fuente NULL (original). Clics e impresiones: MAX por campaña-día (se cuentan una sola vez), excepto Meta, que trae región real y se suma. Consulta: cmp/mensual.sql.
A13: Diferencias | B13: ① Actual vs Plataforma = Actual / Plataforma − 1 · ② Nueva vs Plataforma = Nueva / Plataforma − 1 · ③ Nueva vs Actual = Nueva / Actual − 1.
