Workbook

Sheet Resumen
A1: Comparativa inversión de medios CO 2026 — Plataformas vs tabla actual vs tabla nueva
A2: Tabla actual: papyrus-data.habi_wh_bi.resumen_inversiones_mkt_co · Tabla nueva: papyrus-master.sellers_comercial_global_dwh.sellers_inversion_marketing_regiones_global_dwh (pais = Colombia, columna spend en USD) · Plataformas: hoja de gasto del equipo (USD). Ene – 22 sep 2026. Sólo gasto.
A4: Plataforma | B4: Gasto plataforma (USD) | C4: Tabla actual | D4: Tabla nueva | E4: ① Actual vs Plat. | F4: ② Nueva vs Plat. | G4: ③ Nueva vs Actual | H4: Veredicto tabla nueva
A5: Meta | B5: =Gasto!C14 | C5: =Gasto!D14 | D5: =Gasto!E14 | E5: =IF(AND(ISNUMBER(C5),ISNUMBER(B5),B5<>0),C5/B5-1,"") | F5: =IF(AND(ISNUMBER(D5),ISNUMBER(B5),B5<>0),D5/B5-1,"") | G5: =IF(AND(ISNUMBER(D5),ISNUMBER(C5),C5<>0),D5/C5-1,"") | H5: Falla: divide el gasto en USD entre ~3,100–4,300 como si fuera COP (US$134 en todo el año)
A6: Google | B6: =Gasto!C25 | C6: =Gasto!D25 | D6: =Gasto!E25 | E6: =IF(AND(ISNUMBER(C6),ISNUMBER(B6),B6<>0),C6/B6-1,"") | F6: =IF(AND(ISNUMBER(D6),ISNUMBER(B6),B6<>0),D6/B6-1,"") | G6: =IF(AND(ISNUMBER(D6),ISNUMBER(C6),C6<>0),D6/C6-1,"") | H6: Falla: duplica el renglón original después del prorrateo (+26% a +38%)
A7: TikTok | B7: =Gasto!C36 | C7: =Gasto!D36 | D7: =Gasto!E36 | E7: =IF(AND(ISNUMBER(C7),ISNUMBER(B7),B7<>0),C7/B7-1,"") | F7: =IF(AND(ISNUMBER(D7),ISNUMBER(B7),B7<>0),D7/B7-1,"") | G7: =IF(AND(ISNUMBER(D7),ISNUMBER(C7),C7<>0),D7/C7-1,"") | H7: Cuadra jun–sep; en feb trae el gasto vacío (US$148)
A8: Bing | B8: =Gasto!C47 | C8: =Gasto!D47 | D8: =Gasto!E47 | E8: =IF(AND(ISNUMBER(C8),ISNUMBER(B8),B8<>0),C8/B8-1,"") | F8: =IF(AND(ISNUMBER(D8),ISNUMBER(B8),B8<>0),D8/B8-1,"") | G8: =IF(AND(ISNUMBER(D8),ISNUMBER(C8),C8<>0),D8/C8-1,"") | H8: Cuadra (±0.7%), salvo junio, que viene vacío (US$622)
A9: TOTAL | B9: =SUM(B5:B8) | C9: =SUM(C5:C8) | D9: =SUM(D5:D8) | E9: =IF(AND(ISNUMBER(C9),ISNUMBER(B9),B9<>0),C9/B9-1,"") | F9: =IF(AND(ISNUMBER(D9),ISNUMBER(B9),B9<>0),D9/B9-1,"") | G9: =IF(AND(ISNUMBER(D9),ISNUMBER(C9),C9<>0),D9/C9-1,"") | H9: La tabla actual cuadra; la nueva no es usable sin corrección
A11: Conclusiones
A12: 1. La tabla actual (resumen_inversiones_mkt_co) cuadra con la hoja de plataforma: diferencias de menos de US$25 por mes en Meta, Bing y TikTok, y en Google ene–may y sep.
A13: 2. Google jun–ago sale +1.4%, +5.3% y +6.6% en la tabla actual, pero la diferencia es exactamente una campaña (gpm-bog-nbn_3, US$8,273 en total) que no aparece en la hoja de plataforma, probablemente por estar eliminada. No es un error de las tablas.
A14: 3. La tabla nueva no cuadra: Meta sale en US$134 para todo el año (−100%), Google +26% a +38% por el renglón original duplicado, y faltan Bing junio y TikTok febrero.
A15: 4. Con la corrección (quitar duplicados en Google y, en Meta, multiplicar spend por el tipo de cambio), Google queda igual a la tabla actual (±0.2%) y Meta igual a la plataforma. Los meses vacíos requieren arreglo en origen (Data Engineering). Detalle: hoja "Hallazgos para DE".

Sheet Gasto
A1: Gasto — Colombia 2026 (USD)
A2: Plataforma = hoja de gasto del equipo (USD). Tabla nueva = SUM(spend) directo, sin corregir. Vacío = la tabla no trae gasto ese mes.
C3: Valores (USD) | G3: Diferencia % (vs. referencia) | K3: Diferencia absoluta
A4: Plataforma | B4: Mes | C4: Plataforma (fuente) | D4: Tabla actual | E4: Tabla nueva | F4: Tabla nueva corregida* | G4: ① Actual vs Plataforma | H4: ② Nueva vs Plataforma | I4: ③ Nueva vs Actual | J4: Nueva corregida vs Plataforma | K4: ① Dif. USD | L4: ② Dif. USD | M4: Nota
A5: Meta | B5: Ene | C5: 52337 | D5: 52332 | E5: 12.19 | F5: 52337.1 | G5: =IF(AND(ISNUMBER(D5),ISNUMBER(C5),C5<>0),D5/C5-1,"") | H5: =IF(AND(ISNUMBER(E5),ISNUMBER(C5),C5<>0),E5/C5-1,"") | I5: =IF(AND(ISNUMBER(E5),ISNUMBER(D5),D5<>0),E5/D5-1,"") | J5: =IF(AND(ISNUMBER(F5),ISNUMBER(C5),C5<>0),F5/C5-1,"") | K5: =IF(AND(ISNUMBER(D5),ISNUMBER(C5)),D5-C5,"") | L5: =IF(AND(ISNUMBER(E5),ISNUMBER(C5)),E5-C5,"")
A6: Meta | B6: Feb | C6: 49329 | D6: 49328 | E6: 13.42 | F6: 49328.51 | G6: =IF(AND(ISNUMBER(D6),ISNUMBER(C6),C6<>0),D6/C6-1,"") | H6: =IF(AND(ISNUMBER(E6),ISNUMBER(C6),C6<>0),E6/C6-1,"") | I6: =IF(AND(ISNUMBER(E6),ISNUMBER(D6),D6<>0),E6/D6-1,"") | J6: =IF(AND(ISNUMBER(F6),ISNUMBER(C6),C6<>0),F6/C6-1,"") | K6: =IF(AND(ISNUMBER(D6),ISNUMBER(C6)),D6-C6,"") | L6: =IF(AND(ISNUMBER(E6),ISNUMBER(C6)),E6-C6,"")
A7: Meta | B7: Mar | C7: 52859 | D7: 52853 | E7: 14.21 | F7: 52859.04 | G7: =IF(AND(ISNUMBER(D7),ISNUMBER(C7),C7<>0),D7/C7-1,"") | H7: =IF(AND(ISNUMBER(E7),ISNUMBER(C7),C7<>0),E7/C7-1,"") | I7: =IF(AND(ISNUMBER(E7),ISNUMBER(D7),D7<>0),E7/D7-1,"") | J7: =IF(AND(ISNUMBER(F7),ISNUMBER(C7),C7<>0),F7/C7-1,"") | K7: =IF(AND(ISNUMBER(D7),ISNUMBER(C7)),D7-C7,"") | L7: =IF(AND(ISNUMBER(E7),ISNUMBER(C7)),E7-C7,"")
A8: Meta | B8: Abr | C8: 43411 | D8: 43413 | E8: 12 | F8: 43411.35 | G8: =IF(AND(ISNUMBER(D8),ISNUMBER(C8),C8<>0),D8/C8-1,"") | H8: =IF(AND(ISNUMBER(E8),ISNUMBER(C8),C8<>0),E8/C8-1,"") | I8: =IF(AND(ISNUMBER(E8),ISNUMBER(D8),D8<>0),E8/D8-1,"") | J8: =IF(AND(ISNUMBER(F8),ISNUMBER(C8),C8<>0),F8/C8-1,"") | K8: =IF(AND(ISNUMBER(D8),ISNUMBER(C8)),D8-C8,"") | L8: =IF(AND(ISNUMBER(E8),ISNUMBER(C8)),E8-C8,"")
A9: Meta | B9: May | C9: 47443 | D9: 47453 | E9: 12.78 | F9: 47443.37 | G9: =IF(AND(ISNUMBER(D9),ISNUMBER(C9),C9<>0),D9/C9-1,"") | H9: =IF(AND(ISNUMBER(E9),ISNUMBER(C9),C9<>0),E9/C9-1,"") | I9: =IF(AND(ISNUMBER(E9),ISNUMBER(D9),D9<>0),E9/D9-1,"") | J9: =IF(AND(ISNUMBER(F9),ISNUMBER(C9),C9<>0),F9/C9-1,"") | K9: =IF(AND(ISNUMBER(D9),ISNUMBER(C9)),D9-C9,"") | L9: =IF(AND(ISNUMBER(E9),ISNUMBER(C9)),E9-C9,"")
A10: Meta | B10: Jun | C10: 50975 | D10: 50976 | E10: 14.59 | F10: 50975.41 | G10: =IF(AND(ISNUMBER(D10),ISNUMBER(C10),C10<>0),D10/C10-1,"") | H10: =IF(AND(ISNUMBER(E10),ISNUMBER(C10),C10<>0),E10/C10-1,"") | I10: =IF(AND(ISNUMBER(E10),ISNUMBER(D10),D10<>0),E10/D10-1,"") | J10: =IF(AND(ISNUMBER(F10),ISNUMBER(C10),C10<>0),F10/C10-1,"") | K10: =IF(AND(ISNUMBER(D10),ISNUMBER(C10)),D10-C10,"") | L10: =IF(AND(ISNUMBER(E10),ISNUMBER(C10)),E10-C10,"")
A11: Meta | B11: Jul | C11: 52247 | D11: 52252 | E11: 16 | F11: 52247.07 | G11: =IF(AND(ISNUMBER(D11),ISNUMBER(C11),C11<>0),D11/C11-1,"") | H11: =IF(AND(ISNUMBER(E11),ISNUMBER(C11),C11<>0),E11/C11-1,"") | I11: =IF(AND(ISNUMBER(E11),ISNUMBER(D11),D11<>0),E11/D11-1,"") | J11: =IF(AND(ISNUMBER(F11),ISNUMBER(C11),C11<>0),F11/C11-1,"") | K11: =IF(AND(ISNUMBER(D11),ISNUMBER(C11)),D11-C11,"") | L11: =IF(AND(ISNUMBER(E11),ISNUMBER(C11)),E11-C11,"")
A12: Meta | B12: Ago | C12: 67713 | D12: 67712 | E12: 21.66 | F12: 67712.57 | G12: =IF(AND(ISNUMBER(D12),ISNUMBER(C12),C12<>0),D12/C12-1,"") | H12: =IF(AND(ISNUMBER(E12),ISNUMBER(C12),C12<>0),E12/C12-1,"") | I12: =IF(AND(ISNUMBER(E12),ISNUMBER(D12),D12<>0),E12/D12-1,"") | J12: =IF(AND(ISNUMBER(F12),ISNUMBER(C12),C12<>0),F12/C12-1,"") | K12: =IF(AND(ISNUMBER(D12),ISNUMBER(C12)),D12-C12,"") | L12: =IF(AND(ISNUMBER(E12),ISNUMBER(C12)),E12-C12,"")
A13: Meta | B13: Sep* | C13: 55220 | D13: 55224 | E13: 17.6 | F13: 55216.62 | G13: =IF(AND(ISNUMBER(D13),ISNUMBER(C13),C13<>0),D13/C13-1,"") | H13: =IF(AND(ISNUMBER(E13),ISNUMBER(C13),C13<>0),E13/C13-1,"") | I13: =IF(AND(ISNUMBER(E13),ISNUMBER(D13),D13<>0),E13/D13-1,"") | J13: =IF(AND(ISNUMBER(F13),ISNUMBER(C13),C13<>0),F13/C13-1,"") | K13: =IF(AND(ISNUMBER(D13),ISNUMBER(C13)),D13-C13,"") | L13: =IF(AND(ISNUMBER(E13),ISNUMBER(C13)),E13-C13,"")
A14: Meta | B14: Total 2026 | C14: =SUM(C5:C13) | D14: =SUM(D5:D13) | E14: =SUM(E5:E13) | F14: =SUM(F5:F13) | G14: =IF(AND(ISNUMBER(D14),ISNUMBER(C14),C14<>0),D14/C14-1,"") | H14: =IF(AND(ISNUMBER(E14),ISNUMBER(C14),C14<>0),E14/C14-1,"") | I14: =IF(AND(ISNUMBER(E14),ISNUMBER(D14),D14<>0),E14/D14-1,"") | J14: =IF(AND(ISNUMBER(F14),ISNUMBER(C14),C14<>0),F14/C14-1,"") | K14: =IF(AND(ISNUMBER(D14),ISNUMBER(C14)),D14-C14,"") | L14: =IF(AND(ISNUMBER(E14),ISNUMBER(C14)),E14-C14,"")
A16: Google | B16: Ene | C16: 49829 | D16: 49828 | E16: 63504 | F16: 49772 | G16: =IF(AND(ISNUMBER(D16),ISNUMBER(C16),C16<>0),D16/C16-1,"") | H16: =IF(AND(ISNUMBER(E16),ISNUMBER(C16),C16<>0),E16/C16-1,"") | I16: =IF(AND(ISNUMBER(E16),ISNUMBER(D16),D16<>0),E16/D16-1,"") | J16: =IF(AND(ISNUMBER(F16),ISNUMBER(C16),C16<>0),F16/C16-1,"") | K16: =IF(AND(ISNUMBER(D16),ISNUMBER(C16)),D16-C16,"") | L16: =IF(AND(ISNUMBER(E16),ISNUMBER(C16)),E16-C16,"")
A17: Google | B17: Feb | C17: 49372 | D17: 49366 | E17: 62608 | F17: 49292 | G17: =IF(AND(ISNUMBER(D17),ISNUMBER(C17),C17<>0),D17/C17-1,"") | H17: =IF(AND(ISNUMBER(E17),ISNUMBER(C17),C17<>0),E17/C17-1,"") | I17: =IF(AND(ISNUMBER(E17),ISNUMBER(D17),D17<>0),E17/D17-1,"") | J17: =IF(AND(ISNUMBER(F17),ISNUMBER(C17),C17<>0),F17/C17-1,"") | K17: =IF(AND(ISNUMBER(D17),ISNUMBER(C17)),D17-C17,"") | L17: =IF(AND(ISNUMBER(E17),ISNUMBER(C17)),E17-C17,"")
A18: Google | B18: Mar | C18: 50122 | D18: 50123 | E18: 64120 | F18: 50103 | G18: =IF(AND(ISNUMBER(D18),ISNUMBER(C18),C18<>0),D18/C18-1,"") | H18: =IF(AND(ISNUMBER(E18),ISNUMBER(C18),C18<>0),E18/C18-1,"") | I18: =IF(AND(ISNUMBER(E18),ISNUMBER(D18),D18<>0),E18/D18-1,"") | J18: =IF(AND(ISNUMBER(F18),ISNUMBER(C18),C18<>0),F18/C18-1,"") | K18: =IF(AND(ISNUMBER(D18),ISNUMBER(C18)),D18-C18,"") | L18: =IF(AND(ISNUMBER(E18),ISNUMBER(C18)),E18-C18,"")
A19: Google | B19: Abr | C19: 52358 | D19: 52353 | E19: 66355 | F19: 52263 | G19: =IF(AND(ISNUMBER(D19),ISNUMBER(C19),C19<>0),D19/C19-1,"") | H19: =IF(AND(ISNUMBER(E19),ISNUMBER(C19),C19<>0),E19/C19-1,"") | I19: =IF(AND(ISNUMBER(E19),ISNUMBER(D19),D19<>0),E19/D19-1,"") | J19: =IF(AND(ISNUMBER(F19),ISNUMBER(C19),C19<>0),F19/C19-1,"") | K19: =IF(AND(ISNUMBER(D19),ISNUMBER(C19)),D19-C19,"") | L19: =IF(AND(ISNUMBER(E19),ISNUMBER(C19)),E19-C19,"")
A20: Google | B20: May | C20: 54603 | D20: 54606 | E20: 70567 | F20: 54543 | G20: =IF(AND(ISNUMBER(D20),ISNUMBER(C20),C20<>0),D20/C20-1,"") | H20: =IF(AND(ISNUMBER(E20),ISNUMBER(C20),C20<>0),E20/C20-1,"") | I20: =IF(AND(ISNUMBER(E20),ISNUMBER(D20),D20<>0),E20/D20-1,"") | J20: =IF(AND(ISNUMBER(F20),ISNUMBER(C20),C20<>0),F20/C20-1,"") | K20: =IF(AND(ISNUMBER(D20),ISNUMBER(C20)),D20-C20,"") | L20: =IF(AND(ISNUMBER(E20),ISNUMBER(C20)),E20-C20,"")
A21: Google | B21: Jun | C21: 48543 | D21: 49239 | E21: 64960 | F21: 49253 | G21: =IF(AND(ISNUMBER(D21),ISNUMBER(C21),C21<>0),D21/C21-1,"") | H21: =IF(AND(ISNUMBER(E21),ISNUMBER(C21),C21<>0),E21/C21-1,"") | I21: =IF(AND(ISNUMBER(E21),ISNUMBER(D21),D21<>0),E21/D21-1,"") | J21: =IF(AND(ISNUMBER(F21),ISNUMBER(C21),C21<>0),F21/C21-1,"") | K21: =IF(AND(ISNUMBER(D21),ISNUMBER(C21)),D21-C21,"") | L21: =IF(AND(ISNUMBER(E21),ISNUMBER(C21)),E21-C21,"") | M21: Incluye US$696 de la campaña gpm-bog-nbn_3, que no está en la hoja de plataforma
A22: Google | B22: Jul | C22: 57509 | D22: 60548 | E22: 79130 | F22: 60514 | G22: =IF(AND(ISNUMBER(D22),ISNUMBER(C22),C22<>0),D22/C22-1,"") | H22: =IF(AND(ISNUMBER(E22),ISNUMBER(C22),C22<>0),E22/C22-1,"") | I22: =IF(AND(ISNUMBER(E22),ISNUMBER(D22),D22<>0),E22/D22-1,"") | J22: =IF(AND(ISNUMBER(F22),ISNUMBER(C22),C22<>0),F22/C22-1,"") | K22: =IF(AND(ISNUMBER(D22),ISNUMBER(C22)),D22-C22,"") | L22: =IF(AND(ISNUMBER(E22),ISNUMBER(C22)),E22-C22,"") | M22: Incluye US$3,043 de gpm-bog-nbn_3 (no está en la hoja de plataforma)
A23: Google | B23: Ago | C23: 68963 | D23: 73496 | E23: 93975 | F23: 73526 | G23: =IF(AND(ISNUMBER(D23),ISNUMBER(C23),C23<>0),D23/C23-1,"") | H23: =IF(AND(ISNUMBER(E23),ISNUMBER(C23),C23<>0),E23/C23-1,"") | I23: =IF(AND(ISNUMBER(E23),ISNUMBER(D23),D23<>0),E23/D23-1,"") | J23: =IF(AND(ISNUMBER(F23),ISNUMBER(C23),C23<>0),F23/C23-1,"") | K23: =IF(AND(ISNUMBER(D23),ISNUMBER(C23)),D23-C23,"") | L23: =IF(AND(ISNUMBER(E23),ISNUMBER(C23)),E23-C23,"") | M23: Incluye US$4,534 de gpm-bog-nbn_3 (no está en la hoja de plataforma)
A24: Google | B24: Sep* | C24: 55181 | D24: 55181 | E24: 69556 | F24: 55183 | G24: =IF(AND(ISNUMBER(D24),ISNUMBER(C24),C24<>0),D24/C24-1,"") | H24: =IF(AND(ISNUMBER(E24),ISNUMBER(C24),C24<>0),E24/C24-1,"") | I24: =IF(AND(ISNUMBER(E24),ISNUMBER(D24),D24<>0),E24/D24-1,"") | J24: =IF(AND(ISNUMBER(F24),ISNUMBER(C24),C24<>0),F24/C24-1,"") | K24: =IF(AND(ISNUMBER(D24),ISNUMBER(C24)),D24-C24,"") | L24: =IF(AND(ISNUMBER(E24),ISNUMBER(C24)),E24-C24,"")
A25: Google | B25: Total 2026 | C25: =SUM(C16:C24) | D25: =SUM(D16:D24) | E25: =SUM(E16:E24) | F25: =SUM(F16:F24) | G25: =IF(AND(ISNUMBER(D25),ISNUMBER(C25),C25<>0),D25/C25-1,"") | H25: =IF(AND(ISNUMBER(E25),ISNUMBER(C25),C25<>0),E25/C25-1,"") | I25: =IF(AND(ISNUMBER(E25),ISNUMBER(D25),D25<>0),E25/D25-1,"") | J25: =IF(AND(ISNUMBER(F25),ISNUMBER(C25),C25<>0),F25/C25-1,"") | K25: =IF(AND(ISNUMBER(D25),ISNUMBER(C25)),D25-C25,"") | L25: =IF(AND(ISNUMBER(E25),ISNUMBER(C25)),E25-C25,"")
A27: TikTok | B27: Ene | C27: 0 | D27: 0 | G27: =IF(AND(ISNUMBER(D27),ISNUMBER(C27),C27<>0),D27/C27-1,"") | H27: =IF(AND(ISNUMBER(E27),ISNUMBER(C27),C27<>0),E27/C27-1,"") | I27: =IF(AND(ISNUMBER(E27),ISNUMBER(D27),D27<>0),E27/D27-1,"") | J27: =IF(AND(ISNUMBER(F27),ISNUMBER(C27),C27<>0),F27/C27-1,"") | K27: =IF(AND(ISNUMBER(D27),ISNUMBER(C27)),D27-C27,"") | L27: =IF(AND(ISNUMBER(E27),ISNUMBER(C27)),E27-C27,"")
A28: TikTok | B28: Feb | C28: 148 | D28: 148 | G28: =IF(AND(ISNUMBER(D28),ISNUMBER(C28),C28<>0),D28/C28-1,"") | H28: =IF(AND(ISNUMBER(E28),ISNUMBER(C28),C28<>0),E28/C28-1,"") | I28: =IF(AND(ISNUMBER(E28),ISNUMBER(D28),D28<>0),E28/D28-1,"") | J28: =IF(AND(ISNUMBER(F28),ISNUMBER(C28),C28<>0),F28/C28-1,"") | K28: =IF(AND(ISNUMBER(D28),ISNUMBER(C28)),D28-C28,"") | L28: =IF(AND(ISNUMBER(E28),ISNUMBER(C28)),E28-C28,"") | M28: La tabla nueva trae el gasto vacío (NULL) en todo el mes
A29: TikTok | B29: Mar | C29: 0 | D29: 0 | G29: =IF(AND(ISNUMBER(D29),ISNUMBER(C29),C29<>0),D29/C29-1,"") | H29: =IF(AND(ISNUMBER(E29),ISNUMBER(C29),C29<>0),E29/C29-1,"") | I29: =IF(AND(ISNUMBER(E29),ISNUMBER(D29),D29<>0),E29/D29-1,"") | J29: =IF(AND(ISNUMBER(F29),ISNUMBER(C29),C29<>0),F29/C29-1,"") | K29: =IF(AND(ISNUMBER(D29),ISNUMBER(C29)),D29-C29,"") | L29: =IF(AND(ISNUMBER(E29),ISNUMBER(C29)),E29-C29,"")
A30: TikTok | B30: Abr | C30: 0 | D30: 0 | G30: =IF(AND(ISNUMBER(D30),ISNUMBER(C30),C30<>0),D30/C30-1,"") | H30: =IF(AND(ISNUMBER(E30),ISNUMBER(C30),C30<>0),E30/C30-1,"") | I30: =IF(AND(ISNUMBER(E30),ISNUMBER(D30),D30<>0),E30/D30-1,"") | J30: =IF(AND(ISNUMBER(F30),ISNUMBER(C30),C30<>0),F30/C30-1,"") | K30: =IF(AND(ISNUMBER(D30),ISNUMBER(C30)),D30-C30,"") | L30: =IF(AND(ISNUMBER(E30),ISNUMBER(C30)),E30-C30,"")
A31: TikTok | B31: May | C31: 0 | D31: 0 | G31: =IF(AND(ISNUMBER(D31),ISNUMBER(C31),C31<>0),D31/C31-1,"") | H31: =IF(AND(ISNUMBER(E31),ISNUMBER(C31),C31<>0),E31/C31-1,"") | I31: =IF(AND(ISNUMBER(E31),ISNUMBER(D31),D31<>0),E31/D31-1,"") | J31: =IF(AND(ISNUMBER(F31),ISNUMBER(C31),C31<>0),F31/C31-1,"") | K31: =IF(AND(ISNUMBER(D31),ISNUMBER(C31)),D31-C31,"") | L31: =IF(AND(ISNUMBER(E31),ISNUMBER(C31)),E31-C31,"")
A32: TikTok | B32: Jun | C32: 1624 | D32: 1626 | E32: 1628 | F32: 1628 | G32: =IF(AND(ISNUMBER(D32),ISNUMBER(C32),C32<>0),D32/C32-1,"") | H32: =IF(AND(ISNUMBER(E32),ISNUMBER(C32),C32<>0),E32/C32-1,"") | I32: =IF(AND(ISNUMBER(E32),ISNUMBER(D32),D32<>0),E32/D32-1,"") | J32: =IF(AND(ISNUMBER(F32),ISNUMBER(C32),C32<>0),F32/C32-1,"") | K32: =IF(AND(ISNUMBER(D32),ISNUMBER(C32)),D32-C32,"") | L32: =IF(AND(ISNUMBER(E32),ISNUMBER(C32)),E32-C32,"")
A33: TikTok | B33: Jul | C33: 5826 | D33: 5819 | E33: 5842 | F33: 5842 | G33: =IF(AND(ISNUMBER(D33),ISNUMBER(C33),C33<>0),D33/C33-1,"") | H33: =IF(AND(ISNUMBER(E33),ISNUMBER(C33),C33<>0),E33/C33-1,"") | I33: =IF(AND(ISNUMBER(E33),ISNUMBER(D33),D33<>0),E33/D33-1,"") | J33: =IF(AND(ISNUMBER(F33),ISNUMBER(C33),C33<>0),F33/C33-1,"") | K33: =IF(AND(ISNUMBER(D33),ISNUMBER(C33)),D33-C33,"") | L33: =IF(AND(ISNUMBER(E33),ISNUMBER(C33)),E33-C33,"")
A34: TikTok | B34: Ago | C34: 4880 | D34: 4884 | E34: 4888 | F34: 4888 | G34: =IF(AND(ISNUMBER(D34),ISNUMBER(C34),C34<>0),D34/C34-1,"") | H34: =IF(AND(ISNUMBER(E34),ISNUMBER(C34),C34<>0),E34/C34-1,"") | I34: =IF(AND(ISNUMBER(E34),ISNUMBER(D34),D34<>0),E34/D34-1,"") | J34: =IF(AND(ISNUMBER(F34),ISNUMBER(C34),C34<>0),F34/C34-1,"") | K34: =IF(AND(ISNUMBER(D34),ISNUMBER(C34)),D34-C34,"") | L34: =IF(AND(ISNUMBER(E34),ISNUMBER(C34)),E34-C34,"")
A35: TikTok | B35: Sep* | C35: 2284 | D35: 2286 | E35: 2285 | F35: 2285 | G35: =IF(AND(ISNUMBER(D35),ISNUMBER(C35),C35<>0),D35/C35-1,"") | H35: =IF(AND(ISNUMBER(E35),ISNUMBER(C35),C35<>0),E35/C35-1,"") | I35: =IF(AND(ISNUMBER(E35),ISNUMBER(D35),D35<>0),E35/D35-1,"") | J35: =IF(AND(ISNUMBER(F35),ISNUMBER(C35),C35<>0),F35/C35-1,"") | K35: =IF(AND(ISNUMBER(D35),ISNUMBER(C35)),D35-C35,"") | L35: =IF(AND(ISNUMBER(E35),ISNUMBER(C35)),E35-C35,"")
A36: TikTok | B36: Total 2026 | C36: =SUM(C27:C35) | D36: =SUM(D27:D35) | E36: =SUM(E27:E35) | F36: =SUM(F27:F35) | G36: =IF(AND(ISNUMBER(D36),ISNUMBER(C36),C36<>0),D36/C36-1,"") | H36: =IF(AND(ISNUMBER(E36),ISNUMBER(C36),C36<>0),E36/C36-1,"") | I36: =IF(AND(ISNUMBER(E36),ISNUMBER(D36),D36<>0),E36/D36-1,"") | J36: =IF(AND(ISNUMBER(F36),ISNUMBER(C36),C36<>0),F36/C36-1,"") | K36: =IF(AND(ISNUMBER(D36),ISNUMBER(C36)),D36-C36,"") | L36: =IF(AND(ISNUMBER(E36),ISNUMBER(C36)),E36-C36,"")
A38: Bing | B38: Ene | C38: 7048 | D38: 7045.21 | E38: 7039 | F38: 7039 | G38: =IF(AND(ISNUMBER(D38),ISNUMBER(C38),C38<>0),D38/C38-1,"") | H38: =IF(AND(ISNUMBER(E38),ISNUMBER(C38),C38<>0),E38/C38-1,"") | I38: =IF(AND(ISNUMBER(E38),ISNUMBER(D38),D38<>0),E38/D38-1,"") | J38: =IF(AND(ISNUMBER(F38),ISNUMBER(C38),C38<>0),F38/C38-1,"") | K38: =IF(AND(ISNUMBER(D38),ISNUMBER(C38)),D38-C38,"") | L38: =IF(AND(ISNUMBER(E38),ISNUMBER(C38)),E38-C38,"")
A39: Bing | B39: Feb | C39: 9151 | D39: 9128.73 | E39: 9127 | F39: 9127 | G39: =IF(AND(ISNUMBER(D39),ISNUMBER(C39),C39<>0),D39/C39-1,"") | H39: =IF(AND(ISNUMBER(E39),ISNUMBER(C39),C39<>0),E39/C39-1,"") | I39: =IF(AND(ISNUMBER(E39),ISNUMBER(D39),D39<>0),E39/D39-1,"") | J39: =IF(AND(ISNUMBER(F39),ISNUMBER(C39),C39<>0),F39/C39-1,"") | K39: =IF(AND(ISNUMBER(D39),ISNUMBER(C39)),D39-C39,"") | L39: =IF(AND(ISNUMBER(E39),ISNUMBER(C39)),E39-C39,"")
A40: Bing | B40: Mar | C40: 8768 | D40: 8766.31 | E40: 8781 | F40: 8781 | G40: =IF(AND(ISNUMBER(D40),ISNUMBER(C40),C40<>0),D40/C40-1,"") | H40: =IF(AND(ISNUMBER(E40),ISNUMBER(C40),C40<>0),E40/C40-1,"") | I40: =IF(AND(ISNUMBER(E40),ISNUMBER(D40),D40<>0),E40/D40-1,"") | J40: =IF(AND(ISNUMBER(F40),ISNUMBER(C40),C40<>0),F40/C40-1,"") | K40: =IF(AND(ISNUMBER(D40),ISNUMBER(C40)),D40-C40,"") | L40: =IF(AND(ISNUMBER(E40),ISNUMBER(C40)),E40-C40,"")
A41: Bing | B41: Abr | C41: 7301 | D41: 7300.24 | E41: 7304 | F41: 7304 | G41: =IF(AND(ISNUMBER(D41),ISNUMBER(C41),C41<>0),D41/C41-1,"") | H41: =IF(AND(ISNUMBER(E41),ISNUMBER(C41),C41<>0),E41/C41-1,"") | I41: =IF(AND(ISNUMBER(E41),ISNUMBER(D41),D41<>0),E41/D41-1,"") | J41: =IF(AND(ISNUMBER(F41),ISNUMBER(C41),C41<>0),F41/C41-1,"") | K41: =IF(AND(ISNUMBER(D41),ISNUMBER(C41)),D41-C41,"") | L41: =IF(AND(ISNUMBER(E41),ISNUMBER(C41)),E41-C41,"")
A42: Bing | B42: May | C42: 2554 | D42: 2553.88 | E42: 2557 | F42: 2557 | G42: =IF(AND(ISNUMBER(D42),ISNUMBER(C42),C42<>0),D42/C42-1,"") | H42: =IF(AND(ISNUMBER(E42),ISNUMBER(C42),C42<>0),E42/C42-1,"") | I42: =IF(AND(ISNUMBER(E42),ISNUMBER(D42),D42<>0),E42/D42-1,"") | J42: =IF(AND(ISNUMBER(F42),ISNUMBER(C42),C42<>0),F42/C42-1,"") | K42: =IF(AND(ISNUMBER(D42),ISNUMBER(C42)),D42-C42,"") | L42: =IF(AND(ISNUMBER(E42),ISNUMBER(C42)),E42-C42,"")
A43: Bing | B43: Jun | C43: 622 | D43: 621.75 | G43: =IF(AND(ISNUMBER(D43),ISNUMBER(C43),C43<>0),D43/C43-1,"") | H43: =IF(AND(ISNUMBER(E43),ISNUMBER(C43),C43<>0),E43/C43-1,"") | I43: =IF(AND(ISNUMBER(E43),ISNUMBER(D43),D43<>0),E43/D43-1,"") | J43: =IF(AND(ISNUMBER(F43),ISNUMBER(C43),C43<>0),F43/C43-1,"") | K43: =IF(AND(ISNUMBER(D43),ISNUMBER(C43)),D43-C43,"") | L43: =IF(AND(ISNUMBER(E43),ISNUMBER(C43)),E43-C43,"") | M43: La tabla nueva trae el gasto vacío (NULL) en todo el mes
...

Sheet Hallazgos para DE
A1: Hallazgos en sellers_inversion_marketing_regiones_global_dwh (Colombia) — qué revisar
A2: Cada caso tiene un ejemplo real y una consulta para reproducirlo. Valores en USD.
A4: # | B4: Problema | C4: Qué pasa (ejemplo real) | D4: Impacto | E4: Qué revisar / cómo debería quedar | F4: Consulta para reproducir
A5: 1 | B5: Meta: gasto en USD tratado como pesos colombianos | C5: La cuenta de Meta de Sellers Colombia está en USD. La tabla toma ese valor como COP y lo divide entre el tipo de cambio (el factor implícito va de ~4,300 en enero a ~3,100 en agosto, según la propia tabla). Ejemplo: 24-ago-2026, hab-col-sel-pai-per-web-mta-mld-oto-med-new: valor_original = 388.72, conversion_cop = 388.72, moneda = "USD", spend = 0.13. Agosto 2026: plataforma US$67,713 · tabla actual US$67,712 · tabla nueva US$21.66. El valor correcto está en valor_original / conversion_cop (67,712.57), que en realidad son dólares. | D5: Meta queda en US$134 para todo 2026 contra US$471,534 reales (−99.97%). Es ~46% de la inversión de Colombia. | E5: Si la cuenta está en USD: spend = conversion_usd = valor_original y conversion_cop = valor_original × tipo de cambio. Es el mismo error que en México (allá divide entre ~17 MXN): la regla parece forzar la moneda local en Facebook en lugar de leer la moneda de la cuenta. | F5: SELECT FORMAT_DATE('%Y-%m',date) mes, SUM(valor_original) valor_original, SUM(spend) spend_usd, SUM(conversion_cop) cop, STRING_AGG(DISTINCT moneda) moneda FROM `papyrus-master.sellers_comercial_global_dwh.sellers_inversion_marketing_regiones_global_dwh` WHERE pais='Colombia' AND plataforma='Facebook' AND date>='2026-01-01' GROUP BY 1 ORDER BY 1
A6: 2 | B6: Google: renglón original duplicado después del prorrateo por área metropolitana | C6: Las campañas se reparten por área metropolitana (fuente = Habimetro / WEB). Además de los renglones repartidos, se queda el renglón ORIGINAL sin repartir (fuente NULL, area_metropolitana = "Sin area metropolitana"). Ejemplo: 24-ago-2026, hab-col-hmt-pai-per-web-gga-gwg-gsr-nal. Los 7 renglones repartidos suman US$778 y el renglón original trae US$777 → la tabla suma US$1,555 contra US$777 reales. | D6: Google queda entre +26% y +38% cada mes. Ene–22 sep: US$140,326 de gasto duplicado. | E6: Cuando una campaña-día se prorratea, eliminar (o no insertar) el renglón original. Regla de control: por (date, plataforma, campana_original), SUM(spend) = gasto de la plataforma. Con esa corrección Google cuadra con la tabla actual (±0.2%). | F6: SELECT date, campana_original, area_metropolitana, fuente, spend FROM `papyrus-master.sellers_comercial_global_dwh.sellers_inversion_marketing_regiones_global_dwh` WHERE pais='Colombia' AND date='2026-08-24' AND campana_original='hab-col-hmt-pai-per-web-gga-gwg-gsr-nal' ORDER BY area_metropolitana
A7: 3 | B7: Meses con gasto vacío (NULL) | C7: Hay renglones con spend, valor_original y conversiones en NULL durante meses completos: • Bing junio 2026: 22 renglones sin gasto; la plataforma y la tabla actual traen US$622. • TikTok febrero 2026: 27 renglones sin gasto; la plataforma y la tabla actual traen US$148. (TikTok ene, mar, abr y may también vienen en NULL, pero ahí la plataforma no tuvo gasto.) | D7: US$770 que no aparecen en la tabla nueva. Poco dinero, pero indica que la carga de esos meses falló. | E7: Revisar la carga de Bing de junio y de TikTok de febrero. Si no hubo gasto, el valor debería ser 0, no NULL. | F7: SELECT plataforma, FORMAT_DATE('%Y-%m',date) mes, COUNT(*) renglones, COUNTIF(spend IS NULL) spend_null FROM `papyrus-master.sellers_comercial_global_dwh.sellers_inversion_marketing_regiones_global_dwh` WHERE pais='Colombia' AND plataforma IN ('Bing','TikTok') AND date BETWEEN '2026-01-01' AND '2026-06-30' GROUP BY 1,2 ORDER BY 1,2
A8: 4 | B8: Etiqueta de moneda inconsistente | C8: La columna moneda dice "USD" en todos los renglones de Colombia, pero en Meta conversion_cop = valor_original, es decir, la tabla trata valor_original como COP. | D8: Confunde a quien use valor_original o moneda para convertir. | E8: Que moneda refleje la moneda real de valor_original (la de la cuenta publicitaria) y que las conversiones (usd, cop, mxn) partan de ella. | F8: (misma consulta del hallazgo 1)
A10: Prueba de aceptación sugerida: para cada plataforma y mes, SUM(spend) de la tabla nueva debe ser igual (±0.5%) a la columna Plataforma de la hoja "Gasto", y SUM(conversion_cop) = SUM(spend) × tipo de cambio del día.

Sheet Metodología
A1: Metodología y fuentes
A2: Cómo se construyó cada columna.
A4: Periodo | B4: 1-ene-2026 a 22-sep-2026 en todas las fuentes. Septiembre es parcial.
A5: Métrica | B5: Sólo gasto en USD (no se compararon clics ni impresiones).
A6: Plataforma | B6: Hoja de gasto del equipo por plataforma y mes (USD, dólares enteros; en Bing el punto es separador de miles, p. ej. 7.048 = 7,048).
A7: Tabla actual | B7: papyrus-data.habi_wh_bi.resumen_inversiones_mkt_co: SUM(spend) por plataforma y mes. Está en USD.
A8: Tabla nueva | B8: papyrus-master.sellers_comercial_global_dwh.sellers_inversion_marketing_regiones_global_dwh con pais = 'Colombia': SUM(spend) (USD) directo.
A9: Tabla nueva corregida | B9: Por (date, plataforma, campana_original): si existe algún renglón con fuente NO nula (prorrateado), se descarta el renglón con fuente NULL (original). Gasto de Meta: spend × tipo de cambio del día, que es igual a conversion_cop (y a valor_original); da el gasto real en USD. Consulta: cmp/co_mensual.sql.
A10: Diferencias | B10: ① Actual vs Plataforma = Actual / Plataforma − 1 · ② Nueva vs Plataforma = Nueva / Plataforma − 1 · ③ Nueva vs Actual = Nueva / Actual − 1.
A11: Google jun–ago | B11: La diferencia de la tabla actual contra la hoja de plataforma es exactamente la campaña hab-col-sel-pai-per-web-gga-gwg-gpm-bog-nbn_3 (jun US$696, jul US$3,043, ago US$4,534), activa del 24-jun al 26-ago.
